2022-04-25 17:42:27,992 ERROR    C:\Users\maxim\PycharmProjects\django\venv\lib\site-packages\django\utils\log.py (<class 'AttributeError'>, AttributeError("'list' object has no attribute 'replace'"), <traceback object at 0x00000227C9507180>) Internal Server Error: /news/123
Traceback (most recent call last):
  File "C:\Users\maxim\PycharmProjects\django\venv\lib\site-packages\django\core\handlers\exception.py", line 47, in inner
    response = get_response(request)
  File "C:\Users\maxim\PycharmProjects\django\venv\lib\site-packages\django\core\handlers\base.py", line 181, in _get_response
    response = wrapped_callback(request, *callback_args, **callback_kwargs)
  File "C:\Users\maxim\PycharmProjects\django\venv\lib\site-packages\django\views\generic\base.py", line 69, in view
    return self.dispatch(request, *args, **kwargs)
  File "C:\Users\maxim\PycharmProjects\django\venv\lib\site-packages\django\views\generic\base.py", line 101, in dispatch
    return handler(request, *args, **kwargs)
  File "C:\Users\maxim\PycharmProjects\django\venv\lib\site-packages\django\views\generic\detail.py", line 107, in get
    context = self.get_context_data(object=self.object)
  File "C:\Users\maxim\OneDrive\Desktop\New_portal_D16\new_portal\news_portal\views.py", line 42, in get_context_data
    context['user_category'] = _(categories)
  File "C:\Users\maxim\PycharmProjects\django\venv\lib\site-packages\django\utils\translation\__init__.py", line 74, in gettext
    return _trans.gettext(message)
  File "C:\Users\maxim\PycharmProjects\django\venv\lib\site-packages\django\utils\translation\trans_real.py", line 352, in gettext
    eol_message = message.replace('\r\n', '\n').replace('\r', '\n')
AttributeError: 'list' object has no attribute 'replace'
2022-04-25 17:42:28,005 ERROR    C:\Users\maxim\PycharmProjects\django\venv\lib\site-packages\django\core\servers\basehttp.py None     "GET /news/123 HTTP/1.1" 500 97292
